Workbook
Name CalendarYear: Januari!$AH$4
Name ColumnTitle13: WerknemerNaam[[#Headers],[Werknemersnamen]]
Name Employee_Absence_Title: Januari!$B$1
Name Key_name: Januari!$B$2
Name KeyCustom1: Januari!$N$2
Name KeyCustom1Label: Januari!$O$2
Name KeyCustom2: Januari!$R$2
Name KeyCustom2Label: Januari!$S$2
Name KeyPersonal: Januari!$G$2
Name KeyPersonalLabel: Januari!$H$2
Name KeySick: Januari!$K$2
Name KeySickLabel: Januari!$L$2
Name KeyVacation: Januari!$C$2
Name KeyVacationLabel: Januari!$D$2
Name MonthName: April!$B$4
Name MonthName: Augustus!$B$4
Name MonthName: December!$B$4
Name MonthName: Februari!$B$4
Name MonthName: Januari!$B$4
Name MonthName: Juli!$B$4
Name MonthName: Juni!$B$4
Name MonthName: Maart!$B$4
Name MonthName: Mei!$B$4
Name MonthName: November!$B$4
Name MonthName: Oktober!$B$4
Name MonthName: September!$B$4
Name Titel1: Januari[[#Headers],[Naam van werknemer]]
Name Titel10: Oktober[[#Headers],[Naam van werknemer]]
Name Titel11: November[[#Headers],[Naam van werknemer]]
Name Titel12: December[[#Headers],[Naam van werknemer]]
Name Titel2: Februari[[#Headers],[Naam van werknemer]]
Name Titel3: Maart[[#Headers],[Naam van werknemer]]
Name Titel4: April[[#Headers],[Naam van werknemer]]
Name Titel5: Mei[[#Headers],[Naam van werknemer]]
Name Titel6: Juni[[#Headers],[Naam van werknemer]]
Name Titel7: Juli[[#Headers],[Naam van werknemer]]
Name Titel8: Augustus[[#Headers],[Naam van werknemer]]
Name Titel9: September[[#Headers],[Naam van werknemer]]

Sheet Januari
B1: Afwezigheidsplanning Werknemers
B2: Sleutel afwezigheidstype | C2: V | D2: Vakantie | G2: P | H2: Persoonlijk | K2: Z | L2: Ziek | N2: A | O2: Ander werk | R2: S | S2: School
AH3: Voer het jaar in:
B4: Januari | C4: Uren | AH4: 2025
C5: =TEXT(WEEKDAY(DATE(CalendarYear,1,1),1),"aaa") -> wo | D5: =TEXT(WEEKDAY(DATE(CalendarYear,1,2),1),"aaa") -> do | E5: =TEXT(WEEKDAY(DATE(CalendarYear,1,3),1),"aaa") -> vr | F5: =TEXT(WEEKDAY(DATE(CalendarYear,1,4),1),"aaa") -> za | G5: =TEXT(WEEKDAY(DATE(CalendarYear,1,5),1),"aaa") -> zo | H5: =TEXT(WEEKDAY(DATE(CalendarYear,1,6),1),"aaa") -> ma | I5: =TEXT(WEEKDAY(DATE(CalendarYear,1,7),1),"aaa") -> di | J5: =TEXT(WEEKDAY(DATE(CalendarYear,1,8),1),"aaa") -> wo | K5: =TEXT(WEEKDAY(DATE(CalendarYear,1,9),1),"aaa") -> do | L5: =TEXT(WEEKDAY(DATE(CalendarYear,1,10),1),"aaa") -> vr | M5: =TEXT(WEEKDAY(DATE(CalendarYear,1,11),1),"aaa") -> za | N5: =TEXT(WEEKDAY(DATE(CalendarYear,1,12),1),"aaa") -> zo | O5: =TEXT(WEEKDAY(DATE(CalendarYear,1,13),1),"aaa") -> ma | P5: =TEXT(WEEKDAY(DATE(CalendarYear,1,14),1),"aaa") -> di | Q5: =TEXT(WEEKDAY(DATE(CalendarYear,1,15),1),"aaa") -> wo | R5: =TEXT(WEEKDAY(DATE(CalendarYear,1,16),1),"aaa") -> do | S5: =TEXT(WEEKDAY(DATE(CalendarYear,1,17),1),"aaa") -> vr | T5: =TEXT(WEEKDAY(DATE(CalendarYear,1,18),1),"aaa") -> za | U5: =TEXT(WEEKDAY(DATE(CalendarYear,1,19),1),"aaa") -> zo | V5: =TEXT(WEEKDAY(DATE(CalendarYear,1,20),1),"aaa") -> ma | W5: =TEXT(WEEKDAY(DATE(CalendarYear,1,21),1),"aaa") -> di | X5: =TEXT(WEEKDAY(DATE(CalendarYear,1,22),1),"aaa") -> wo | Y5: =TEXT(WEEKDAY(DATE(CalendarYear,1,23),1),"aaa") -> do | Z5: =TEXT(WEEKDAY(DATE(CalendarYear,1,24),1),"aaa") -> vr | AA5: =TEXT(WEEKDAY(DATE(CalendarYear,1,25),1),"aaa") -> za | AB5: =TEXT(WEEKDAY(DATE(CalendarYear,1,26),1),"aaa") -> zo | AC5: =TEXT(WEEKDAY(DATE(CalendarYear,1,27),1),"aaa") -> ma | AD5: =TEXT(WEEKDAY(DATE(CalendarYear,1,28),1),"aaa") -> di | AE5: =TEXT(WEEKDAY(DATE(CalendarYear,1,29),1),"aaa") -> wo | AF5: =TEXT(WEEKDAY(DATE(CalendarYear,1,30),1),"aaa") -> do | AG5: =TEXT(WEEKDAY(DATE(CalendarYear,1,31),1),"aaa") -> vr
B6: Naam van werknemer | C6: 1 | D6: 2 | E6: 3 | F6: 4 | G6: 5 | H6: 6 | I6: 7 | J6: 8 | K6: 9 | L6: 10 | M6: 11 | N6: 12 | O6: 13 | P6: 14 | Q6: 15 | R6: 16 | S6: 17 | T6: 18 | U6: 19 | V6: 20 | W6: 21 | X6: 22 | Y6: 23 | Z6: 24 | AA6: 25 | AB6: 26 | AC6: 27 | AD6: 28 | AE6: 29 | AF6: 30 | AG6: 31 | AH6: Totaal aantal uren
B7: Biragoye Isaac | C7: A | D7: A | E7: 3.5 | F7: 3.5 | G7: 3.5 | H7: V | I7: A | J7: A | K7: A | L7: 3.5 | M7: 3.5 | N7: 3.5 | O7: V | P7: A | Q7: A | R7: A | S7: 3.5 | T7: V | U7: 3.5 | V7: V | W7: A | X7: A | Y7: A | Z7: 3.5 | AA7: 3.5 | AB7: 3.5 | AC7: V | AD7: A | AE7: A | AF7: A | AG7: 3.5 | AH7: =SUM(Januari!$C7:$AG7) -> 42
B8: Cinar Rafet | C8: A | D8: A | E8: A | F8: A | G8: A | H8: V | I8: A | J8: A | K8: A | L8: A | M8: A | N8: A | O8: V | P8: A | Q8: A | R8: A | S8: A | T8: A | U8: A | V8: V | W8: A | X8: A | Y8: A | Z8: A | AA8: A | AB8: A | AC8: V | AD8: A | AE8: A | AF8: A | AG8: A | AH8: =SUM(Januari!$C8:$AG8) -> 0
B9: Cygora Lukasz Jan | C9: A | D9: A | E9: A | F9: A | G9: A | H9: V | I9: A | J9: A | K9: A | L9: A | M9: A | N9: A | O9: V | P9: A | Q9: A | R9: A | S9: A | T9: A | U9: A | V9: V | W9: A | X9: A | Y9: A | Z9: A | AA9: A | AB9: A | AC9: V | AD9: A | AE9: A | AF9: A | AG9: A | AH9: =SUM(Januari!$C9:$AG9) -> 0
B10: El Karmoudi Taufik | C10: 5 | D10: A | E10: 5 | F10: 5 | G10: 5 | H10: V | I10: A | J10: A | K10: A | L10: 5 | M10: 5 | N10: 5 | O10: V | P10: A | Q10: A | R10: A | S10: 5 | T10: 5 | U10: 5 | V10: V | W10: A | X10: A | Y10: A | Z10: 5 | AA10: 5 | AB10: 5 | AC10: V | AD10: A | AE10: A | AF10: A | AG10: 5 | AH10: =SUM(Januari!$C10:$AG10) -> 70
B11: El Maazouzi Abdelilah | C11: 4 | D11: 4 | E11: 4 | F11: 4 | G11: 4 | H11: V | I11: A | J11: A | K11: A | L11: A | M11: 4 | N11: 4 | O11: V | P11: A | Q11: 4 | R11: 4 | S11: 4 | T11: 4 | U11: 4 | V11: V | W11: A | X11: A | Y11: A | Z11: A | AA11: 4 | AB11: 4 | AC11: V | AD11: A | AE11: 4 | AF11: 4 | AG11: V | AH11: =SUM(Januari!$C11:$AG11) -> 64
B12: Gultekin Muhammed A | C12: 4 | D12: A | E12: 4 | F12: 4 | G12: 4 | H12: V | I12: A | J12: A | K12: A | L12: 4 | M12: 4 | N12: 4 | O12: V | P12: A | Q12: A | R12: A | S12: 4 | T12: 4 | U12: 4 | V12: V | W12: A | X12: A | Y12: A | Z12: 4 | AA12: 4 | AB12: 4 | AC12: V | AD12: A | AE12: A | AF12: A | AG12: 4 | AH12: =SUM(Januari!$C12:$AG12) -> 56
B13: Gultekin Muhammed E | C13: A | D13: A | E13: 4 | F13: 4 | G13: 4 | H13: V | I13: A | J13: A | K13: A | L13: 4 | M13: 4 | N13: 4 | O13: V | P13: A | Q13: A | R13: A | S13: 4 | T13: 4 | U13: 4 | V13: V | W13: A | X13: A | Y13: A | Z13: 4 | AA13: 4 | AB13: 4 | AC13: V | AD13: A | AE13: A | AF13: A | AG13: 4 | AH13: =SUM(Januari!$C13:$AG13) -> 52
B14: Irakoze Patrick | C14: 3 | D14: A | E14: 3.5 | F14: 3.5 | G14: 3.5 | H14: V | I14: A | J14: A | K14: A | L14: 3.5 | M14: 3.5 | N14: 3.5 | O14: V | P14: 3.5 | Q14: 3.5 | R14: A | S14: 3.5 | T14: 4 | U14: 3.5 | V14: V | W14: A | X14: A | Y14: A | Z14: A | AA14: A | AB14: A | AC14: V | AD14: A | AE14: A | AF14: A | AG14: A | AH14: =SUM(Januari!$C14:$AG14) -> 42
B15: Kacar Abdullah | C15: A | D15: A | E15: A | F15: A | G15: A | H15: V | I15: A | J15: A | K15: A | L15: A | M15: A | N15: A | O15: V | P15: A | Q15: A | R15: A | S15: A | T15: A | U15: A | V15: V | W15: A | X15: A | Y15: A | Z15: A | AA15: A | AB15: A | AC15: V | AD15: A | AE15: A | AF15: A | AG15: A | AH15: =SUM(Januari!$C15:$AG15) -> 0
B16: Kefes Levent | C16: A | D16: A | E16: A | F16: A | G16: A | H16: V | I16: A | J16: A | K16: A | L16: A | M16: A | N16: A | O16: V | P16: A | Q16: A | R16: A | S16: A | T16: A | U16: A | V16: V | W16: A | X16: A | Y16: A | Z16: A | AA16: A | AB16: A | AC16: V | AD16: A | AE16: A | AF16: A | AG16: A | AH16: =SUM(Januari!$C16:$AG16) -> 0
B17: Moualdine Ali | C17: 5 | D17: A | E17: 5 | F17: 5 | G17: 5 | H17: V | I17: A | J17: A | K17: A | L17: 5 | M17: 5 | N17: 5 | O17: V | P17: A | Q17: A | R17: A | S17: 5 | T17: 5 | U17: 5 | V17: V | W17: A | X17: A | Y17: A | Z17: 5 | AA17: 5 | AB17: 5 | AC17: V | AD17: A | AE17: A | AF17: A | AG17: 5 | AH17: =SUM(Januari!$C17:$AG17) -> 70
B18: Nsengimana Alexis | C18: 3 | D18: A | E18: A | F18: 3.5 | G18: 3.5 | H18: V | I18: A | J18: A | K18: A | L18: 3.5 | M18: 3.5 | N18: 3.5 | O18: V | P18: A | Q18: A | R18: A | S18: A | T18: 3.5 | U18: 3.5 | V18: V | W18: A | X18: A | Y18: A | Z18: 3.5 | AA18: 3.5 | AB18: 3.5 | AC18: V | AD18: A | AE18: A | AF18: A | AG18: A | AH18: =SUM(Januari!$C18:$AG18) -> 38
B19: =MonthName&" Totaal" -> Januari Totaal | AH19: =SUBTOTAL(109,Januari[Totaal aantal uren]) -> 434

Sheet Februari
B1: =Employee_Absence_Title -> Afwezigheidsplanning Werknemers
B2: Sleutel afwezigheidstype | C2: V | D2: Vakantie | G2: P | H2: Persoonlijk | K2: Z | L2: Ziek | O2: Aangepast 1 | S2: Aangepast 2
B4: Februari | C4: Afwezigheidsdatums | AH4: =CalendarYear -> 2025
C5: =TEXT(WEEKDAY(DATE(CalendarYear,2,1),1),"aaa") -> za | D5: =TEXT(WEEKDAY(DATE(CalendarYear,2,2),1),"aaa") -> zo | E5: =TEXT(WEEKDAY(DATE(CalendarYear,2,3),1),"aaa") -> ma | F5: =TEXT(WEEKDAY(DATE(CalendarYear,2,4),1),"aaa") -> di | G5: =TEXT(WEEKDAY(DATE(CalendarYear,2,5),1),"aaa") -> wo | H5: =TEXT(WEEKDAY(DATE(CalendarYear,2,6),1),"aaa") -> do | I5: =TEXT(WEEKDAY(DATE(CalendarYear,2,7),1),"aaa") -> vr | J5: =TEXT(WEEKDAY(DATE(CalendarYear,2,8),1),"aaa") -> za | K5: =TEXT(WEEKDAY(DATE(CalendarYear,2,9),1),"aaa") -> zo | L5: =TEXT(WEEKDAY(DATE(CalendarYear,2,10),1),"aaa") -> ma | M5: =TEXT(WEEKDAY(DATE(CalendarYear,2,11),1),"aaa") -> di | N5: =TEXT(WEEKDAY(DATE(CalendarYear,2,12),1),"aaa") -> wo | O5: =TEXT(WEEKDAY(DATE(CalendarYear,2,13),1),"aaa") -> do | P5: =TEXT(WEEKDAY(DATE(CalendarYear,2,14),1),"aaa") -> vr | Q5: =TEXT(WEEKDAY(DATE(CalendarYear,2,15),1),"aaa") -> za | R5: =TEXT(WEEKDAY(DATE(CalendarYear,2,16),1),"aaa") -> zo | S5: =TEXT(WEEKDAY(DATE(CalendarYear,2,17),1),"aaa") -> ma | T5: =TEXT(WEEKDAY(DATE(CalendarYear,2,18),1),"aaa") -> di | U5: =TEXT(WEEKDAY(DATE(CalendarYear,2,19),1),"aaa") -> wo | V5: =TEXT(WEEKDAY(DATE(CalendarYear,2,20),1),"aaa") -> do | W5: =TEXT(WEEKDAY(DATE(CalendarYear,2,21),1),"aaa") -> vr | X5: =TEXT(WEEKDAY(DATE(CalendarYear,2,22),1),"aaa") -> za | Y5: =TEXT(WEEKDAY(DATE(CalendarYear,2,23),1),"aaa") -> zo | Z5: =TEXT(WEEKDAY(DATE(CalendarYear,2,24),1),"aaa") -> ma | AA5: =TEXT(WEEKDAY(DATE(CalendarYear,2,25),1),"aaa") -> di | AB5: =TEXT(WEEKDAY(DATE(CalendarYear,2,26),1),"aaa") -> wo | AC5: =TEXT(WEEKDAY(DATE(CalendarYear,2,27),1),"aaa") -> do | AD5: =TEXT(WEEKDAY(DATE(CalendarYear,2,28),1),"aaa") -> vr | AE5: =TEXT(WEEKDAY(DATE(CalendarYear,2,29),1),"aaa") -> za
B6: Naam van werknemer | C6: 1 | D6: 2 | E6: 3 | F6: 4 | G6: 5 | H6: 6 | I6: 7 | J6: 8 | K6: 9 | L6: 10 | M6: 11 | N6: 12 | O6: 13 | P6: 14 | Q6: 15 | R6: 16 | S6: 17 | T6: 18 | U6: 19 | V6: 20 | W6: 21 | X6: 22 | Y6: 23 | Z6: 24 | AA6: 25 | AB6: 26 | AC6: 27 | AD6: 28 | AE6: 29 | AH6: Totaal aantal uren
B7: Biragoye Isaac | C7: 3.5 | D7: 3.5 | E7: V | F7: V | G7: V | H7: V | I7: V | J7: V | K7: V | L7: V | M7: V | N7: V | O7: A | P7: 3.5 | Q7: 3.5 | R7: 3.5 | S7: V | T7: A | U7: A | V7: A | W7: 3.5 | X7: 3.5 | Y7: 3.5 | Z7: V | AA7: A | AB7: A | AC7: A | AD7: 3.5 | AH7: =SUM(Februari[[#This Row],[1]:[28]]) -> 31.5
B8: Cinar Rafet | C8: 4 | D8: 4 | E8: V | F8: A | G8: A | H8: A | I8: A | J8: A | K8: A | L8: V | M8: A | N8: A | O8: A | P8: A | Q8: A | R8: A | S8: V | T8: A | U8: A | V8: A | W8: A | X8: A | Y8: V | Z8: V | AA8: A | AB8: A | AC8: A | AD8: A | AH8: =SUM(Februari[[#This Row],[1]:[28]]) -> 8
B9: Cygora Lukasz Jan | C9: A | D9: A | E9: V | F9: A | G9: A | H9: A | I9: A | J9: A | K9: A | L9: V | M9: A | N9: A | O9: A | P9: A | Q9: A | R9: A | S9: V | T9: A | U9: A | V9: A | W9: A | X9: A | Y9: A | Z9: V | AA9: A | AB9: A | AC9: A | AD9: A | AH9: =SUM(Februari[[#This Row],[1]:[28]]) -> 0
B10: El Karmoudi Taufik | C10: 5 | D10: 5 | E10: V | F10: A | G10: A | H10: 5 | I10: 5 | J10: 5 | K10: 5 | L10: V | M10: A | N10: A | O10: A | P10: A | Q10: 5 | R10: 5 | S10: V | T10: A | U10: A | V10: A | W10: 5 | X10: 5 | Y10: 5 | Z10: V | AA10: A | AB10: A | AC10: A | AD10: 5 | AH10: =SUM(Februari[[#This Row],[1]:[28]]) -> 60
B11: El Maazouzi Abdelilah | C11: V | D11: V | E11: V | F11: V | G11: V | H11: V | I11: V | J11: V | K11: V | L11: V | M11: V | N11: V | O11: V | P11: V | Q11: V | R11: V | S11: V | T11: V | U11: V | V11: V | W11: V | X11: V | Y11: V | Z11: V | AA11: A | AB11: A | AC11: A | AD11: A | AH11: =SUM(Februari[[#This Row],[1]:[28]]) -> 0
B12: Gultekin Muhammed A | C12: 4 | D12: 4 | E12: V | F12: A | G12: A | H12: A | I12: A | J12: 4 | K12: 4 | L12: V | M12: A | N12: A | O12: A | P12: A | Q12: 4 | R12: 4 | S12: V | T12: A | U12: A | V12: A | W12: 4 | X12: 4 | Y12: 4 | Z12: V | AA12: A | AB12: A | AC12: A | AD12: 4 | AH12: =SUM(Februari[[#This Row],[1]:[28]]) -> 40
B13: Gultekin Muhammed E | C13: 4 | D13: 4 | E13: V | F13: A | G13: A | H13: A | I13: 4 | J13: 4 | K13: 4 | L13: V | M13: A | N13: A | O13: A | P13: 4 | Q13: 4 | R13: 4 | S13: V | T13: A | U13: A | V13: A | W13: 4 | X13: 4 | Y13: 4 | Z13: V | AA13: A | AB13: A | AC13: A | AD13: 4 | AH13: =SUM(Februari[[#This Row],[1]:[28]]) -> 48
B14: Irakoze Patrick | C14: A | D14: A | E14: V | F14: A | G14: A | H14: A | I14: A | J14: A | K14: A | L14: V | M14: A | N14: A | O14: A | P14: A | Q14: A | R14: A | S14: V | T14: A | U14: A | V14: A | W14: A | X14: A | Y14: A | Z14: V | AA14: A | AB14: A | AC14: A | AD14: A | AH14: =SUM(Februari[[#This Row],[1]:[28]]) -> 0
B15: Kacar Abdullah | C15: A | D15: A | E15: V | F15: A | G15: A | H15: A | I15: A | J15: A | K15: A | L15: V | M15: A | N15: A | O15: A | P15: A | Q15: A | R15: A | S15: V | T15: A | U15: A | V15: A | W15: A | X15: A | Y15: A | Z15: V | AA15: A | AB15: A | AC15: A | AD15: A | AH15: =SUM(Februari[[#This Row],[1]:[28]]) -> 0
B16: Kefes Levent | C16: 3.5 | D16: 3.5 | E16: V | F16: A | G16: A | H16: A | I16: A | J16: 4 | K16: 3.5 | L16: V | M16: A | N16: A | O16: A | P16: A | Q16: A | R16: A | S16: V | T16: A | U16: A | V16: A | W16: A | X16: A | Y16: A | Z16: V | AA16: A | AB16: A | AC16: A | AD16: A | AH16: =SUM(Februari[[#This Row],[1]:[28]]) -> 14.5
B17: Moualdine Ali | C17: 5 | D17: 5 | E17: V | F17: A | G17: A | H17: A | I17: 5 | J17: 5 | K17: 5 | L17: V | M17: A | N17: A | O17: A | P17: 5 | Q17: 5 | R17: 5 | S17: V | T17: A | U17: A | V17: 5 | W17: 5 | X17: 5 | Y17: 5 | Z17: V | AA17: A | AB17: A | AC17: A | AD17: A | AH17: =SUM(Februari[[#This Row],[1]:[28]]) -> 60
B18: Nsengimana Alexis | C18: 3.5 | D18: 3.5 | E18: V | F18: A | G18: A | H18: A | I18: 3.5 | J18: 3.5 | K18: 3.5 | L18: V | M18: A | N18: A | O18: A | P18: A | Q18: V | R18: 3.5 | S18: V | T18: A | U18: A | V18: A | W18: V | X18: V | Y18: V | Z18: V | AA18: A | AB18: A | AC18: A | AD18: A | AH18: =SUM(Februari[[#This Row],[1]:[28]]) -> 21
B19: =MonthName&" Totaal" -> Februari Totaal | C19: =SUBTOTAL(109,Februari[1]) -> 32.5 | D19: =SUBTOTAL(109,Februari[2]) -> 32.5 | E19: =SUBTOTAL(109,Februari[3]) -> 0 | F19: =SUBTOTAL(109,Februari[4]) -> 0 | G19: =SUBTOTAL(109,Februari[5]) -> 0 | H19: =SUBTOTAL(109,Februari[6]) -> 5 | I19: =SUBTOTAL(109,Februari[7]) -> 17.5 | J19: =SUBTOTAL(109,Februari[8]) -> 25.5 | K19: =SUBTOTAL(109,Februari[9]) -> 25 | L19: =SUBTOTAL(109,Februari[10]) -> 0 | M19: =SUBTOTAL(109,Februari[11]) -> 0 | N19: =SUBTOTAL(109,Februari[12]) -> 0 | O19: =SUBTOTAL(109,Februari[13]) -> 0 | P19: =SUBTOTAL(109,Februari[14]) -> 12.5 | Q19: =SUBTOTAL(109,Februari[15]) -> 21.5 | R19: =SUBTOTAL(109,Februari[16]) -> 25 | S19: =SUBTOTAL(109,Februari[17]) -> 0 | T19: =SUBTOTAL(109,Februari[18]) -> 0 | U19: =SUBTOTAL(109,Februari[19]) -> 0 | V19: =SUBTOTAL(109,Februari[20]) -> 5 | W19: =SUBTOTAL(109,Februari[21]) -> 21.5 | X19: =SUBTOTAL(109,Februari[22]) -> 21.5 | Y19: =SUBTOTAL(109,Februari[23]) -> 21.5 | Z19: =SUBTOTAL(109,Februari[24]) -> 0 | AA19: =SUBTOTAL(109,Februari[25]) -> 0 | AB19: =SUBTOTAL(109,Februari[26]) -> 0 | AC19: =SUBTOTAL(109,Februari[27]) -> 0 | AD19: =SUBTOTAL(109,Februari[28]) -> 16.5 | AE19: =SUBTOTAL(109,Februari[29]) -> 0 | AF19: =SUBTOTAL(109,Februari[[ ]]) -> 0 | AH19: =SUBTOTAL(109,Februari[Totaal aantal uren]) -> 283

Sheet Maart
B1: =Employee_Absence_Title -> Afwezigheidsplanning Werknemers
B2: Sleutel afwezigheidstype | C2: V | D2: Vakantie | G2: P | H2: Persoonlijk | K2: Z | L2: Ziek | O2: Aangepast 1 | S2: Aangepast 2
B4: Maart | C4: Afwezigheidsdatums | AH4: =CalendarYear -> 2025
C5: =TEXT(WEEKDAY(DATE(CalendarYear,3,1),1),"aaa") -> za | D5: =TEXT(WEEKDAY(DATE(CalendarYear,3,2),1),"aaa") -> zo | E5: =TEXT(WEEKDAY(DATE(CalendarYear,3,3),1),"aaa") -> ma | F5: =TEXT(WEEKDAY(DATE(CalendarYear,3,4),1),"aaa") -> di | G5: =TEXT(WEEKDAY(DATE(CalendarYear,3,5),1),"aaa") -> wo | H5: =TEXT(WEEKDAY(DATE(CalendarYear,3,6),1),"aaa") -> do | I5: =TEXT(WEEKDAY(DATE(CalendarYear,3,7),1),"aaa") -> vr | J5: =TEXT(WEEKDAY(DATE(CalendarYear,3,8),1),"aaa") -> za | K5: =TEXT(WEEKDAY(DATE(CalendarYear,3,9),1),"aaa") -> zo | L5: =TEXT(WEEKDAY(DATE(CalendarYear,3,10),1),"aaa") -> ma | M5: =TEXT(WEEKDAY(DATE(CalendarYear,3,11),1),"aaa") -> di | N5: =TEXT(WEEKDAY(DATE(CalendarYear,3,12),1),"aaa") -> wo | O5: =TEXT(WEEKDAY(DATE(CalendarYear,3,13),1),"aaa") -> do | P5: =TEXT(WEEKDAY(DATE(CalendarYear,3,14),1),"aaa") -> vr | Q5: =TEXT(WEEKDAY(DATE(CalendarYear,3,15),1),"aaa") -> za | R5: =TEXT(WEEKDAY(DATE(CalendarYear,3,16),1),"aaa") -> zo | S5: =TEXT(WEEKDAY(DATE(CalendarYear,3,17),1),"aaa") -> ma | T5: =TEXT(WEEKDAY(DATE(CalendarYear,3,18),1),"aaa") -> di | U5: =TEXT(WEEKDAY(DATE(CalendarYear,3,19),1),"aaa") -> wo | V5: =TEXT(WEEKDAY(DATE(CalendarYear,3,20),1),"aaa") -> do | W5: =TEXT(WEEKDAY(DATE(CalendarYear,3,21),1),"aaa") -> vr | X5: =TEXT(WEEKDAY(DATE(CalendarYear,3,22),1),"aaa") -> za | Y5: =TEXT(WEEKDAY(DATE(CalendarYear,3,23),1),"aaa") -> zo | Z5: =TEXT(WEEKDAY(DATE(CalendarYear,3,24),1),"aaa") -> ma | AA5: =TEXT(WEEKDAY(DATE(CalendarYear,3,25),1),"aaa") -> di | AB5: =TEXT(WEEKDAY(DATE(CalendarYear,3,26),1),"aaa") -> wo | AC5: =TEXT(WEEKDAY(DATE(CalendarYear,3,27),1),"aaa") -> do | AD5: =TEXT(WEEKDAY(DATE(CalendarYear,3,28),1),"aaa") -> vr | AE5: =TEXT(WEEKDAY(DATE(CalendarYear,3,29),1),"aaa") -> za | AF5: =TEXT(WEEKDAY(DATE(CalendarYear,3,30),1),"aaa") -> zo | AG5: =TEXT(WEEKDAY(DATE(CalendarYear,3,31),1),"aaa") -> ma
B6: Naam van werknemer | C6: 1 | D6: 2 | E6: 3 | F6: 4 | G6: 5 | H6: 6 | I6: 7 | J6: 8 | K6: 9 | L6: 10 | M6: 11 | N6: 12 | O6: 13 | P6: 14 | Q6: 15 | R6: 16 | S6: 17 | T6: 18 | U6: 19 | V6: 20 | W6: 21 | X6: 22 | Y6: 23 | Z6: 24 | AA6: 25 | AB6: 26 | AC6: 27 | AD6: 28 | AE6: 29 | AF6: 30 | AG6: 31 | AH6: Totaal aantal uren
B7: Biragoye Isaac | C7: 3.5 | D7: 3.5 | E7: V | F7: A | G7: A | H7: A | I7: 3.5 | J7: V | K7: 3.5 | L7: V | M7: A | N7: A | O7: A | P7: 4 | Q7: 4 | R7: 3.5 | S7: V | T7: A | U7: A | V7: A | W7: 3.5 | X7: 3.5 | Y7: 3.5 | Z7: V | AA7: A | AB7: A | AC7: A | AD7: 3.5 | AE7: 3 | AF7: 3.5 | AG7: V | AH7: =SUM(Maart[[#This Row],[1]:[31]]) -> 46
B8: Cinar Rafet | C8: 4 | D8: 4 | E8: V | F8: A | G8: A | H8: A | I8: A | J8: A | K8: A | L8: V | M8: A | N8: A | O8: A | P8: A | Q8: A | R8: A | S8: V | T8: A | U8: A | V8: A | W8: A | X8: A | Y8: A | Z8: V | AA8: A | AB8: A | AC8: A | AD8: A | AE8: A | AF8: A | AG8: V | AH8: =SUM(Maart[[#This Row],[1]:[31]]) -> 8
B9: Cygora Lukasz Jan | C9: A | D9: A | E9: V | F9: A | G9: A | H9: A | I9: A | J9: A | K9: A | L9: V | M9: A | N9: A | O9: A | P9: A | Q9: A | R9: A | S9: V | T9: A | U9: A | V9: A | W9: A | X9: A | Y9: A | Z9: V | AA9: A | AB9: A | AC9: A | AD9: A | AE9: A | AF9: A | AG9: V | AH9: =SUM(Maart[[#This Row],[1]:[31]]) -> 0
B10: El Karmoudi Taufik | C10: 5 | D10: 5 | E10: V | F10: A | G10: A | H10: A | I10: 5 | J10: 5 | K10: 5 | L10: V | M10: A | N10: A | O10: A | P10: 5 | Q10: 5 | R10: 5 | S10: V | T10: A | U10: A | V10: A | W10: 5 | X10: 5 | Y10: 5 | Z10: V | AA10: A | AB10: A | AC10: A | AD10: 5 | AE10: 5 | AF10: 5 | AG10: V | AH10: =SUM(Maart[[#This Row],[1]:[31]]) -> 70
B11: Eranil Mehmet Fatih | C11: 3.5 | D11: 3.5 | E11: V | F11: A | G11: A | H11: A | I11: A | J11: 4 | K11: 3.5 | L11: V | M11: A | N11: A | O11: A | P11: A | Q11: 3.5 | R11: 3.5 | S11: V | T11: A | U11: A | V11: A | W11: A | X11: 4 | Y11: 4 | Z11: V | AA11: A | AB11: A | AC11: A | AD11: 3.5 | AE11: 4 | AF11: 3.5 | AG11: V | AH11: =SUM(Maart[[#This Row],[1]:[31]]) -> 40.5
B12: El Maazouzi Abdelilah | C12: 4 | D12: 4 | E12: V | F12: A | G12: A | H12: A | I12: A | J12: 4 | K12: 4 | L12: V | M12: A | N12: 4 | O12: 4 | P12: 4 | Q12: 4 | R12: 4 | S12: V | T12: A | U12: A | V12: A | W12: A | X12: 4 | Y12: 4 | Z12: V | AA12: A | AB12: 4 | AC12: 4 | AD12: 4 | AE12: 4 | AF12: 4 | AG12: V | AH12: =SUM(Maart[[#This Row],[1]:[31]]) -> 64
B13: Gultekin Muhammed A | C13: 4 | D13: 4 | E13: V | F13: A | G13: A | H13: A | I13: 4 | J13: 4 | K13: 4 | L13: V | M13: A | N13: A | O13: A | P13: 4 | Q13: 4 | R13: 4 | S13: V | T13: A | U13: A | V13: A | W13: 4 | X13: 4 | Y13: 4 | Z13: V | AA13: A | AB13: A | AC13: A | AD13: 4 | AE13: 4 | AF13: 4 | AG13: V | AH13: =SUM(Maart[[#This Row],[1]:[31]]) -> 56
B14: Gultekin Muhammed E | C14: 4 | D14: 4 | E14: V | F14: A | G14: A | H14: A | I14: 4 | J14: 4 | K14: 4 | L14: V | M14: A | N14: A | O14: A | P14: 4 | Q14: 4 | R14: 4 | S14: V | T14: A | U14: A | V14: A | W14: 4 | X14: 4 | Y14: 4 | Z14: V | AA14: A | AB14: A | AC14: A | AD14: 4 | AE14: 4 | AF14: 4 | AG14: V | AH14: =SUM(Maart[[#This Row],[1]:[31]]) -> 56
B15: Irakoze Patrick | C15: A | D15: A | E15: V | F15: A | G15: A | H15: A | I15: A | J15: A | K15: A | L15: V | M15: A | N15: A | O15: A | P15: A | Q15: A | R15: A | S15: V | T15: A | U15: A | V15: A | W15: A | X15: A | Y15: A | Z15: V | AA15: A | AB15: A | AC15: A | AD15: A | AE15: A | AF15: A | AG15: V | AH15: =SUM(Januari!$C14:$AG14) -> 42
B16: Kacar Abdullah | C16: V | D16: V | E16: V | F16: A | G16: A | H16: A | I16: A | J16: A | K16: A | L16: V | M16: A | N16: A | O16: A | P16: A | Q16: A | R16: A | S16: V | T16: A | U16: A | V16: A | W16: A | X16: A | Y16: A | Z16: V | AA16: A | AB16: A | AC16: A | AD16: A | AE16: A | AF16: A | AG16: V | AH16: =SUM(Maart[[#This Row],[1]:[31]]) -> 0
B17: Kefes Levent | C17: 3.5 | D17: 3.5 | E17: V | F17: A | G17: A | H17: A | I17: A | J17: 3.5 | K17: 3.5 | L17: V | M17: A | N17: A | O17: A | P17: A | Q17: 3.5 | R17: 3.5 | S17: V | T17: A | U17: A | V17: A | W17: A | X17: 3.5 | Y17: 3.5 | Z17: V | AA17: A | AB17: A | AC17: A | AD17: A | AE17: 3.5 | AF17: 3.5 | AG17: V | AH17: =SUM(Maart[[#This Row],[1]:[31]]) -> 35
B18: Moualdine Ali | C18: 5 | D18: 5 | E18: V | F18: A | G18: A | H18: A | I18: 5 | J18: 5 | K18: 5 | L18: V | M18: A | N18: A | O18: A | P18: 5 | Q18: 5 | R18: 5 | S18: V | T18: A | U18: A | V18: A | W18: 5 | X18: 5 | Y18: 5 | Z18: V | AA18: A | AB18: A | AC18: A | AD18: 5 | AE18: 5 | AF18: 5 | AG18: V | AH18: =SUM(Maart[[#This Row],[1]:[31]]) -> 70
B19: Nsengimana Alexis | C19: 3.5 | D19: 3.5 | E19: V | F19: A | G19: A | H19: A | I19: 3.5 | J19: 3.5 | K19: 3.5 | L19: V | M19: A | N19: A | O19: A | P19: A | Q19: 3.5 | R19: 3.5 | S19: V | T19: A | U19: A | V19: A | W19: 3.5 | X19: 3.5 | Y19: 3.5 | Z19: V | AA19: A | AB19: A | AC19: A | AD19: A | AE19: 3.5 | AF19: 3.5 | AG19: V | AH19: =SUM(Maart[[#This Row],[1]:[31]]) -> 42
B20: =MonthName&" Totaal" -> Maart Totaal | C20: =SUM(Maart!C8:C19) -> 36.5 | D20: =SUM(Maart!D8:D19) -> 36.5 | E20: =SUM(Maart!E7:E19) -> 0 | F20: =SUM(Maart!F7:F19) -> 0 | G20: =SUM(Maart!G7:G19) -> 0 | H20: =SUM(Maart!H7:H19) -> 0 | I20: =SUM(Maart!I7:I19) -> 25 | J20: =SUM(Maart!J7:J19) -> 33 | K20: =SUM(Maart!K7:K19) -> 36 | L20: =SUM(Maart!L7:L19) -> 0 | ... AG20: =SUM(Maart!AG7:AG19) -> 0 | AH20: =SUBTOTAL(109,Maart[Totaal aantal uren]) -> 529.5

Sheet April
B1: =Employee_Absence_Title -> Afwezigheidsplanning Werknemers
B2: Sleutel afwezigheidstype | C2: V | D2: Vakantie | G2: P | H2: Persoonlijk | K2: Z | L2: Ziek | O2: Aangepast 1 | S2: Aangepast 2
B4: April | C4: Afwezigheidsdatums | AH4: =CalendarYear -> 2025
C5: =TEXT(WEEKDAY(DATE(CalendarYear,4,1),1),"aaa") -> di | D5: =TEXT(WEEKDAY(DATE(CalendarYear,4,2),1),"aaa") -> wo | E5: =TEXT(WEEKDAY(DATE(CalendarYear,4,3),1),"aaa") -> do | F5: =TEXT(WEEKDAY(DATE(CalendarYear,4,4),1),"aaa") -> vr | G5: =TEXT(WEEKDAY(DATE(CalendarYear,4,5),1),"aaa") -> za | H5: =TEXT(WEEKDAY(DATE(CalendarYear,4,6),1),"aaa") -> zo | I5: =TEXT(WEEKDAY(DATE(CalendarYear,4,7),1),"aaa") -> ma | J5: =TEXT(WEEKDAY(DATE(CalendarYear,4,8),1),"aaa") -> di | K5: =TEXT(WEEKDAY(DATE(CalendarYear,4,9),1),"aaa") -> wo | L5: =TEXT(WEEKDAY(DATE(CalendarYear,4,10),1),"aaa") -> do | M5: =TEXT(WEEKDAY(DATE(CalendarYear,4,11),1),"aaa") -> vr | N5: =TEXT(WEEKDAY(DATE(CalendarYear,4,12),1),"aaa") -> za | O5: =TEXT(WEEKDAY(DATE(CalendarYear,4,13),1),"aaa") -> zo | P5: =TEXT(WEEKDAY(DATE(CalendarYear,4,14),1),"aaa") -> ma | Q5: =TEXT(WEEKDAY(DATE(CalendarYear,4,15),1),"aaa") -> di | R5: =TEXT(WEEKDAY(DATE(CalendarYear,4,16),1),"aaa") -> wo | S5: =TEXT(WEEKDAY(DATE(CalendarYear,4,17),1),"aaa") -> do | T5: =TEXT(WEEKDAY(DATE(CalendarYear,4,18),1),"aaa") -> vr | U5: =TEXT(WEEKDAY(DATE(CalendarYear,4,19),1),"aaa") -> za | V5: =TEXT(WEEKDAY(DATE(CalendarYear,4,20),1),"aaa") -> zo | W5: =TEXT(WEEKDAY(DATE(CalendarYear,4,21),1),"aaa") -> ma | X5: =TEXT(WEEKDAY(DATE(CalendarYear,4,22),1),"aaa") -> di | Y5: =TEXT(WEEKDAY(DATE(CalendarYear,4,23),1),"aaa") -> wo | Z5: =TEXT(WEEKDAY(DATE(CalendarYear,4,24),1),"aaa") -> do | AA5: =TEXT(WEEKDAY(DATE(CalendarYear,4,25),1),"aaa") -> vr | AB5: =TEXT(WEEKDAY(DATE(CalendarYear,4,26),1),"aaa") -> za | AC5: =TEXT(WEEKDAY(DATE(CalendarYear,4,27),1),"aaa") -> zo | AD5: =TEXT(WEEKDAY(DATE(CalendarYear,4,28),1),"aaa") -> ma | AE5: =TEXT(WEEKDAY(DATE(CalendarYear,4,29),1),"aaa") -> di | AF5: =TEXT(WEEKDAY(DATE(CalendarYear,4,30),1),"aaa") -> wo
B6: Naam van werknemer | C6: 1 | D6: 2 | E6: 3 | F6: 4 | G6: 5 | H6: 6 | I6: 7 | J6: 8 | K6: 9 | L6: 10 | M6: 11 | N6: 12 | O6: 13 | P6: 14 | Q6: 15 | R6: 16 | S6: 17 | T6: 18 | U6: 19 | V6: 20 | W6: 21 | X6: 22 | Y6: 23 | Z6: 24 | AA6: 25 | AB6: 26 | AC6: 27 | AD6: 28 | AE6: 29 | AF6: 30 | AH6: Totaal aantal uren
B7: Biragoye Isaac | C7: A | D7: A | E7: A | F7: 3.5 | G7: 3.5 | H7: 3.5 | I7: V | J7: A | K7: A | L7: A | M7: 3.5 | N7: 3.5 | O7: 3.5 | P7: V | Q7: A | R7: A | S7: A | T7: V | U7: V | V7: V | W7: V | X7: A | Y7: A | Z7: A | AA7: 3.5 | AB7: 3.5 | AC7: 3.5 | AD7: V | AE7: A | AF7: A | AH7: =SUM(April[[#This Row],[1]:[ ]]) -> 31.5
B8: Cinar Rafet | C8: A | D8: A | E8: A | F8: 4 | G8: V | H8: 4 | I8: V | J8: A | K8: A | L8: A | M8: 4 | N8: 4 | O8: 4 | P8: V | Q8: A | R8: A | S8: A | T8: A | U8: A | V8: A | W8: V | X8: A | Y8: A | Z8: A | AA8: A | AB8: A | AC8: A | AD8: V | AE8: A | AF8: A | AH8: =SUM(April[[#This Row],[1]:[ ]]) -> 20
B9: Eranil Mehmet Fatih | C9: A | D9: A | E9: A | F9: 3.5 | G9: 3.5 | H9: 3.5 | I9: V | J9: A | K9: A | L9: A | M9: A | N9: 3.5 | O9: 3.5 | P9: V | Q9: A | R9: A | S9: A | T9: 3.5 | U9: 3.5 | V9: 3.5 | W9: 3.5 | X9: A | Y9: A | Z9: A | AA9: A | AB9: 3.5 | AC9: 3.5 | AD9: V | AE9: A | AF9: A | AH9: =SUM(April[[#This Row],[1]:[ ]]) -> 38.5
B10: El Karmoudi Taufik | C10: A | D10: A | E10: A | F10: 5 | G10: 5 | H10: 5 | I10: V | J10: A | K10: A | L10: A | M10: 5 | N10: 5 | O10: 5 | P10: V | Q10: A | R10: A | S10: A | T10: 5 | U10: 5 | V10: 5 | W10: 5 | X10: A | Y10: A | Z10: A | AA10: 5 | AB10: 5 | AC10: 5 | AD10: V | AE10: A | AF10: A | AH10: =SUM(April[[#This Row],[1]:[ ]]) -> 65
B11: El Maazouzi Abdelilah | C11: A | D11: A | E11: A | F11: A | G11: 4 | H11: 4 | I11: V | J11: A | K11: 4 | L11: 4 | M11: 4 | N11: V | O11: 4 | P11: V | Q11: A | R11: A | S11: A | T11: A | U11: 4 | V11: 4 | W11: 4 | X11: A | Y11: 4 | Z11: 4 | AA11: 4 | AB11: 4 | AC11: 4 | AD11: V | AE11: A | AF11: A | AH11: =SUM(April[[#This Row],[1]:[ ]]) -> 56
B12: Gultekin Muhammed A | C12: A | D12: A | E12: A | F12: 5 | G12: 5 | H12: 5 | I12: V | J12: A | K12: A | L12: A | M12: 5 | N12: 5 | O12: 5 | P12: V | Q12: A | R12: A | S12: A | T12: 5 | U12: 5 | V12: 5 | W12: 5 | X12: A | Y12: A | Z12: A | AA12: 5 | AB12: 5 | AC12: 5 | AD12: V | AE12: A | AF12: A | AH12: =SUM(April[[#This Row],[1]:[ ]]) -> 65
B13: Gultekin Muhammed E | C13: A | D13: 4 | E13: 4 | F13: 4 | G13: 4 | H13: V | I13: V | J13: A | K13: A | L13: 4 | M13: 4 | N13: 4 | O13: 4 | P13: V | Q13: A | R13: A | S13: 4 | T13: 4 | U13: 4 | V13: 4 | W13: 4 | X13: A | Y13: A | Z13: A | AA13: 4 | AB13: 4 | AC13: 4 | AD13: V | AE13: A | AF13: A | AH13: =SUM(April[[#This Row],[1]:[ ]]) -> 64
B14: Irakoze Patrick | C14: A | D14: A | E14: A | F14: A | G14: A | H14: A | I14: V | J14: A | K14: A | L14: A | M14: A | N14: A | O14: A | P14: V | Q14: A | R14: A | S14: A | T14: A | U14: A | V14: A | W14: V | X14: 4 | Y14: A | Z14: A | AA14: A | AB14: A | AC14: A | AD14: V | AE14: A | AF14: A | AH14: =SUM(Januari!$C14:$AG14) -> 42
B15: Gultekin Eyyub | C15: A | D15: A | E15: A | F15: A | G15: 4 | H15: 4 | I15: V | J15: A | K15: A | L15: A | M15: A | P15: V | Q15: A | R15: A | S15: A | T15: 4 | U15: 4 | V15: 4 | W15: 4 | X15: A | Y15: A | Z15: A | AA15: 4 | AB15: 4 | AC15: 4 | AD15: V | AE15: A | AF15: A | AH15: =SUM(April[[#This Row],[1]:[ ]]) -> 36
B16: Kefes Levent | C16: A | D16: A | E16: A | F16: A | G16: 3.5 | H16: 3.5 | I16: V | J16: A | K16: A | L16: A | M16: A | N16: 3.5 | O16: 3.5 | P16: V | Q16: A | R16: A | S16: A | T16: A | U16: 3.5 | V16: 3.5 | W16: V | X16: A | Y16: A | Z16: A | AA16: A | AB16: 3.5 | AC16: 3.5 | AD16: V | AE16: A | AF16: A | AH16: =SUM(April[[#This Row],[1]:[ ]]) -> 28
B17: Moualdine Ali | C17: A | D17: A | E17: A | F17: 5 | G17: 5 | H17: 5 | I17: V | J17: A | K17: A | L17: A | M17: 5 | N17: 5 | O17: 5 | P17: V | Q17: A | R17: A | S17: A | T17: 5 | U17: 5 | V17: 5 | W17: 5 | X17: A | Y17: A | Z17: A | AA17: 5 | AB17: 5 | AC17: 5 | AD17: V | AE17: A | AF17: A | AH17: =SUM(April[[#This Row],[1]:[ ]]) -> 65
B18: Nsengimana Alexis | C18: A | D18: A | E18: A | F18: 3.5 | G18: 3.5 | H18: V | I18: V | J18: A | K18: A | L18: A | M18: A | N18: A | O18: A | P18: V | Q18: A | R18: A | S18: A | T18: A | U18: A | V18: A | W18: V | X18: A | Y18: A | Z18: A | AA18: A | AB18: A | AC18: A | AD18: V | AE18: A | AF18: A | AH18: =SUM(April[[#This Row],[1]:[ ]]) -> 7
B19: =MonthName&" Totaal" -> April Totaal | C19: =SUM(C7:C18) -> 0 | D19: =SUM(D8:D18) -> 4 | E19: =SUM(E7:E18) -> 4 | F19: =SUM(F7:F18) -> 33.5 | G19: =SUM(G7:G18) -> 41 | H19: =SUM(H7:H18) -> 37.5 | I19: =SUM(I7:I18) -> 0 | J19: =SUM(J7:J18) -> 0 | K19: =SUM(K7:K18) -> 4 | L19: =SUM(L7:L18) -> 8 | ... AG19: =SUM(AG7:AG18) -> 0 | AH19: =SUBTOTAL(109,April[Totaal aantal uren]) -> 518

Sheet Mei
B1: =Employee_Absence_Title -> Afwezigheidsplanning Werknemers
B2: Sleutel afwezigheidstype | C2: V | D2: Vakantie | G2: P | H2: Persoonlijk | K2: Z | L2: Ziek | O2: Aangepast 1 | S2: Aangepast 2
B4: Mei | C4: Afwezigheidsdatums | AH4: =CalendarYear -> 2025
C5: =TEXT(WEEKDAY(DATE(CalendarYear,5,1),1),"aaa") -> do | D5: =TEXT(WEEKDAY(DATE(CalendarYear,5,2),1),"aaa") -> vr | E5: =TEXT(WEEKDAY(DATE(CalendarYear,5,3),1),"aaa") -> za | F5: =TEXT(WEEKDAY(DATE(CalendarYear,5,4),1),"aaa") -> zo | G5: =TEXT(WEEKDAY(DATE(CalendarYear,5,5),1),"aaa") -> ma | H5: =TEXT(WEEKDAY(DATE(CalendarYear,5,6),1),"aaa") -> di | I5: =TEXT(WEEKDAY(DATE(CalendarYear,5,7),1),"aaa") -> wo | J5: =TEXT(WEEKDAY(DATE(CalendarYear,5,8),1),"aaa") -> do | K5: =TEXT(WEEKDAY(DATE(CalendarYear,5,9),1),"aaa") -> vr | L5: =TEXT(WEEKDAY(DATE(CalendarYear,5,10),1),"aaa") -> za | M5: =TEXT(WEEKDAY(DATE(CalendarYear,5,11),1),"aaa") -> zo | N5: =TEXT(WEEKDAY(DATE(CalendarYear,5,12),1),"aaa") -> ma | O5: =TEXT(WEEKDAY(DATE(CalendarYear,5,13),1),"aaa") -> di | P5: =TEXT(WEEKDAY(DATE(CalendarYear,5,14),1),"aaa") -> wo | Q5: =TEXT(WEEKDAY(DATE(CalendarYear,5,15),1),"aaa") -> do | R5: =TEXT(WEEKDAY(DATE(CalendarYear,5,16),1),"aaa") -> vr | S5: =TEXT(WEEKDAY(DATE(CalendarYear,5,17),1),"aaa") -> za | T5: =TEXT(WEEKDAY(DATE(CalendarYear,5,18),1),"aaa") -> zo | U5: =TEXT(WEEKDAY(DATE(CalendarYear,5,19),1),"aaa") -> ma | V5: =TEXT(WEEKDAY(DATE(CalendarYear,5,20),1),"aaa") -> di | W5: =TEXT(WEEKDAY(DATE(CalendarYear,5,21),1),"aaa") -> wo | X5: =TEXT(WEEKDAY(DATE(CalendarYear,5,22),1),"aaa") -> do | Y5: =TEXT(WEEKDAY(DATE(CalendarYear,5,23),1),"aaa") -> vr | Z5: =TEXT(WEEKDAY(DATE(CalendarYear,5,24),1),"aaa") -> za | AA5: =TEXT(WEEKDAY(DATE(CalendarYear,5,25),1),"aaa") -> zo | AB5: =TEXT(WEEKDAY(DATE(CalendarYear,5,26),1),"aaa") -> ma | AC5: =TEXT(WEEKDAY(DATE(CalendarYear,5,27),1),"aaa") -> di | AD5: =TEXT(WEEKDAY(DATE(CalendarYear,5,28),1),"aaa") -> wo | AE5: =TEXT(WEEKDAY(DATE(CalendarYear,5,29),1),"aaa") -> do | AF5: =TEXT(WEEKDAY(DATE(CalendarYear,5,30),1),"aaa") -> vr | AG5: =TEXT(WEEKDAY(DATE(CalendarYear,5,31),1),"aaa") -> za
B6: Naam van werknemer | C6: 1 | D6: 2 | E6: 3 | F6: 4 | G6: 5 | H6: 6 | I6: 7 | J6: 8 | K6: 9 | L6: 10 | M6: 11 | N6: 12 | O6: 13 | P6: 14 | Q6: 15 | R6: 16 | S6: 17 | T6: 18 | U6: 19 | V6: 20 | W6: 21 | X6: 22 | Y6: 23 | Z6: 24 | AA6: 25 | AB6: 26 | AC6: 27 | AD6: 28 | AE6: 29 | AF6: 30 | AG6: 31 | AH6: Totaal aantal uren
B7: Biragoye Isaac | C7: 3.5 | D7: 3.5 | E7: 3.5 | F7: 3 | G7: V | H7: A | I7: A | J7: A | K7: 3.5 | L7: 3.5 | M7: 3.5 | N7: V | O7: A | P7: A | Q7: A | R7: 3 | S7: 3.5 | T7: 3.5 | U7: V | V7: A | W7: A | X7: A | Y7: 3 | Z7: 3.5 | AA7: V | AB7: V | AC7: A | AD7: A | AE7: 3.5 | AF7: 3.5 | AG7: 3.5 | AH7: =SUM(Mei[[#This Row],[1]:[31]]) -> 51
B8: Cinar Rafet | C8: 4 | D8: 4 | E8: A | F8: A | G8: V | H8: A | I8: A | J8: A | K8: V | L8: V | M8: V | N8: V | O8: V | P8: V | Q8: V | R8: V | S8: V | T8: V | U8: V | V8: V | W8: V | X8: V | Y8: V | Z8: V | AA8: V | AB8: V | AC8: V | AD8: V | AE8: V | AF8: V | AG8: V | AH8: =SUM(Mei[[#This Row],[1]:[31]]) -> 8
B9: Eranil Mehmet Fatih | C9: 3.5 | D9: 3.5 | E9: 3.5 | F9: 3.5 | G9: V | H9: A | I9: A | J9: A | K9: A | L9: 3.5 | M9: 3.5 | N9: V | O9: A | P9: A | Q9: A | R9: 3.5 | S9: 3.5 | T9: 3.5 | U9: V | V9: A | W9: A | X9: A | Y9: A | Z9: 3.5 | AA9: 3.5 | AB9: V | AC9: A | AD9: A | AE9: 3.5 | AF9: 3.5 | AG9: 3.5 | AH9: =SUM(Mei[[#This Row],[1]:[31]]) -> 49
B10: El Karmoudi Taufik | C10: A | D10: V | E10: V | F10: V | G10: V | H10: A | I10: A | J10: A | K10: 5 | L10: 5 | M10: 5 | N10: V | O10: A | P10: A | Q10: A | R10: 5 | S10: 5 | T10: 5 | U10: V | V10: A | W10: A | X10: A | Y10: 5 | Z10: 5 | AA10: 5 | AB10: V | AC10: A | AD10: A | AE10: 5 | AF10: 5 | AG10: 5 | AH10: =SUM(Mei[[#This Row],[1]:[31]]) -> 60
B11: El Maazouzi Abdelilah | C11: A | D11: A | E11: 4 | F11: 4 | G11: V | H11: A | I11: 4 | J11: 4 | K11: 4 | L11: 4 | M11: 4 | N11: V | O11: A | P11: A | Q11: A | R11: A | S11: 4 | T11: 4 | U11: V | V11: A | W11: 4 | X11: 4 | Y11: 4 | Z11: 4 | AA11: 4 | AB11: V | AC11: A | AD11: A | AE11: 4 | AF11: A | AG11: 4 | AH11: =SUM(Mei[[#This Row],[1]:[31]]) -> 64
B12: Gultekin Muhammed A | C12: 5 | D12: 5 | E12: 5 | F12: 5 | G12: V | H12: A | I12: A | J12: A | K12: A | L12: 5 | M12: 5 | N12: V | O12: A | P12: A | Q12: A | R12: 5 | S12: 5 | T12: 5 | U12: V | V12: A | W12: A | X12: A | Y12: A | Z12: 5 | AA12: 5 | AB12: V | AC12: A | AD12: A | AE12: 5 | AF12: 5 | AG12: 5 | AH12: =SUM(Mei[[#This Row],[1]:[31]]) -> 70
B13: Gultekin Muhammed E | C13: 4 | D13: 4 | E13: 4 | F13: 4 | G13: V | H13: A | I13: A | J13: 4 | K13: 4 | L13: 4 | M13: 4 | N13: V | O13: A | P13: A | Q13: 4 | R13: 4 | S13: 4 | T13: 4 | U13: V | V13: A | W13: A | X13: 4 | Y13: 4 | Z13: 4 | AA13: 4 | AB13: V | AC13: A | AD13: A | AE13: 4 | AF13: 4 | AG13: 4 | AH13: =SUM(Mei[[#This Row],[1]:[31]]) -> 76
B14: Irakoze Patrick | C14: 3.5 | D14: 3.5 | E14: 3.5 | F14: 3.5 | G14: V | H14: 3.5 | I14: 3.5 | J14: A | K14: A | L14: A | M14: 3.5 | N14: V | O14: A | P14: 3.5 | Q14: A | R14: A | S14: A | T14: 3.5 | U14: V | V14: 3.5 | W14: A | X14: A | Y14: 3.5 | Z14: 3 | AA14: 3.5 | AB14: V | AC14: A | AD14: A | AE14: A | AF14: 3.5 | AG14: V | AH14: =SUM(Mei[[#This Row],[1]:[31]]) -> 48.5
B15: Gultekin Eyyub | C15: A | D15: A | E15: 4 | F15: 4 | G15: V | H15: A | I15: A | J15: A | K15: 4 | L15: 4 | M15: 4 | N15: V | O15: A | P15: A | Q15: A | R15: A | S15: 4 | T15: 4 | U15: V | V15: A | W15: A | X15: A | Y15: A | Z15: 4 | AA15: 4 | AB15: V | AC15: A | AD15: A | AE15: 4 | AF15: 4 | AG15: 4 | AH15: =SUM(Mei[[#This Row],[1]:[31]]) -> 48
B16: Kefes Levent | C16: A | D16: A | E16: 3.5 | F16: 3.5 | G16: V | H16: A | I16: A | J16: A | K16: A | L16: 3.5 | M16: 3.5 | N16: V | O16: A | P16: A | Q16: A | R16: A | S16: 3.5 | T16: 3.5 | U16: V | V16: A | W16: A | X16: A | Y16: A | Z16: 3.5 | AA16: 3.5 | AB16: V | AC16: A | AD16: A | AE16: A | AF16: A | AG16: A | AH16: =SUM(Mei[[#This Row],[1]:[31]]) -> 28
B17: Moualdine Ali | C17: 5 | D17: 5 | E17: 5 | F17: 5 | G17: V | H17: A | I17: A | J17: A | K17: 5 | L17: 5 | M17: 5 | N17: V | O17: A | P17: A | Q17: A | R17: 5 | S17: 5 | T17: 5 | U17: V | V17: A | W17: A | X17: A | Y17: 5 | Z17: 5 | AA17: 5 | AB17: V | AC17: A | AD17: A | AE17: 5 | AF17: 5 | AG17: 5 | AH17: =SUM(Mei[[#This Row],[1]:[31]]) -> 80
B18: =MonthName&" Totaal" -> Mei Totaal | C18: =SUM(C7:C17) -> 28.5 | D18: =SUM(D7:D17) -> 28.5 | E18: =SUM(E7:E17) -> 36 | F18: =SUM(F7:F17) -> 35.5 | G18: =SUM(G7:G17) -> 0 | H18: =SUM(H7:H17) -> 3.5 | I18: =SUM(I7:I17) -> 7.5 | J18: =SUM(J7:J17) -> 8 | ... AG18: =SUM(AG7:AG17) -> 34 | AH18: =SUBTOTAL(109,Mei[Totaal aantal uren]) -> 582.5

Sheet Juni
B1: =Employee_Absence_Title -> Afwezigheidsplanning Werknemers
B2: Sleutel afwezigheidstype | C2: V | D2: Vakantie | G2: P | H2: Persoonlijk | K2: Z | L2: Ziek | O2: Aangepast 1 | S2: Aangepast 2
B4: Juni | C4: Afwezigheidsdatums | AH4: =CalendarYear -> 2025
C5: =TEXT(WEEKDAY(DATE(CalendarYear,6,1),1),"aaa") -> zo | D5: =TEXT(WEEKDAY(DATE(CalendarYear,6,2),1),"aaa") -> ma | E5: =TEXT(WEEKDAY(DATE(CalendarYear,6,3),1),"aaa") -> di | F5: =TEXT(WEEKDAY(DATE(CalendarYear,6,4),1),"aaa") -> wo | G5: =TEXT(WEEKDAY(DATE(CalendarYear,6,5),1),"aaa") -> do | H5: =TEXT(WEEKDAY(DATE(CalendarYear,6,6),1),"aaa") -> vr | I5: =TEXT(WEEKDAY(DATE(CalendarYear,6,7),1),"aaa") -> za | J5: =TEXT(WEEKDAY(DATE(CalendarYear,6,8),1),"aaa") -> zo | K5: =TEXT(WEEKDAY(DATE(CalendarYear,6,9),1),"aaa") -> ma | L5: =TEXT(WEEKDAY(DATE(CalendarYear,6,10),1),"aaa") -> di | M5: =TEXT(WEEKDAY(DATE(CalendarYear,6,11),1),"aaa") -> wo | N5: =TEXT(WEEKDAY(DATE(CalendarYear,6,12),1),"aaa") -> do | O5: =TEXT(WEEKDAY(DATE(CalendarYear,6,13),1),"aaa") -> vr | P5: =TEXT(WEEKDAY(DATE(CalendarYear,6,14),1),"aaa") -> za | Q5: =TEXT(WEEKDAY(DATE(CalendarYear,6,15),1),"aaa") -> zo | R5: =TEXT(WEEKDAY(DATE(CalendarYear,6,16),1),"aaa") -> ma | S5: =TEXT(WEEKDAY(DATE(CalendarYear,6,17),1),"aaa") -> di | T5: =TEXT(WEEKDAY(DATE(CalendarYear,6,18),1),"aaa") -> wo | U5: =TEXT(WEEKDAY(DATE(CalendarYear,6,19),1),"aaa") -> do | V5: =TEXT(WEEKDAY(DATE(CalendarYear,6,20),1),"aaa") -> vr | W5: =TEXT(WEEKDAY(DATE(CalendarYear,6,21),1),"aaa") -> za | X5: =TEXT(WEEKDAY(DATE(CalendarYear,6,22),1),"aaa") -> zo | Y5: =TEXT(WEEKDAY(DATE(CalendarYear,6,23),1),"aaa") -> ma | Z5: =TEXT(WEEKDAY(DATE(CalendarYear,6,24),1),"aaa") -> di | AA5: =TEXT(WEEKDAY(DATE(CalendarYear,6,25),1),"aaa") -> wo | AB5: =TEXT(WEEKDAY(DATE(CalendarYear,6,26),1),"aaa") -> do | AC5: =TEXT(WEEKDAY(DATE(CalendarYear,6,27),1),"aaa") -> vr | AD5: =TEXT(WEEKDAY(DATE(CalendarYear,6,28),1),"aaa") -> za | AE5: =TEXT(WEEKDAY(DATE(CalendarYear,6,29),1),"aaa") -> zo | AF5: =TEXT(WEEKDAY(DATE(CalendarYear,6,30),1),"aaa") -> ma
B6: Naam van werknemer | C6: 1 | D6: 2 | E6: 3 | F6: 4 | G6: 5 | H6: 6 | I6: 7 | J6: 8 | K6: 9 | L6: 10 | M6: 11 | N6: 12 | O6: 13 | P6: 14 | Q6: 15 | R6: 16 | S6: 17 | T6: 18 | U6: 19 | V6: 20 | W6: 21 | X6: 22 | Y6: 23 | Z6: 24 | AA6: 25 | AB6: 26 | AC6: 27 | AD6: 28 | AE6: 29 | AF6: 30 | AH6: Totaal aantal uren
B7: Biragoye Isaac | C7: 3.5 | D7: V | E7: A | F7: A | G7: A | H7: 3.5 | I7: 3.5 | J7: 3.5 | K7: 3.5 | L7: A | M7: A | N7: A | O7: 3 | P7: 3.5 | Q7: 3.5 | R7: V | S7: A | T7: A | U7: A | V7: 3.5 | W7: 3.5 | X7: V | Y7: V | Z7: V | AA7: V | AB7: V | AC7: V | AD7: V | AE7: V | AF7: V | AH7: =SUM(Juni[[#This Row],[1]:[30]]) -> 34.5
B8: Eranil Mehmet Fatih | C8: 3.5 | D8: V | E8: A | F8: A | G8: A | H8: A | I8: 3.5 | J8: 3.5 | K8: 3.5 | L8: A | M8: A | N8: A | O8: A | P8: 3.5 | Q8: 3.5 | R8: V | S8: A | T8: A | U8: A | V8: A | W8: 3 | X8: 4 | Y8: V | Z8: A | AA8: A | AB8: A | AC8: 3.5 | AD8: 3.5 | AE8: 3.5 | AF8: V | AH8: =SUM(Juni[[#This Row],[1]:[30]]) -> 38.5
B9: El Karmoudi Taufik | C9: 5 | D9: V | E9: A | F9: A | G9: A | H9: 5 | I9: 5 | J9: 5 | K9: 5 | L9: A | M9: A | N9: A | O9: 5 | P9: 5 | Q9: 5 | R9: V | S9: A | T9: A | U9: A | V9: 5 | W9: 5 | X9: 5 | Y9: V | Z9: A | AA9: A | AB9: A | AC9: 5 | AD9: 5 | AE9: 5 | AF9: V | AH9: =SUM(Juni[[#This Row],[1]:[30]]) -> 70
B10: El Maazouzi Abdelilah | C10: 4 | D10: V | E10: A | F10: 4 | G10: 4 | H10: 4 | I10: 4 | J10: 4 | K10: V | L10: A | M10: A | N10: A | O10: A | P10: 4 | Q10: 4 | R10: V | S10: A | T10: 4 | U10: 4 | V10: 4 | W10: 4 | X10: 4 | Y10: V | Z10: A | AA10: A | AB10: A | AC10: A | AD10: 4 | AE10: 4 | AF10: V | AH10: =SUM(Juni[[#This Row],[1]:[30]]) -> 60
B11: Gultekin Muhammed A | C11: 5 | D11: V | E11: A | F11: A | G11: A | H11: 5 | I11: 5 | J11: 5 | K11: 5 | L11: A | M11: A | N11: A | O11: 5 | P11: 5 | Q11: 5 | R11: V | S11: A | T11: A | U11: A | V11: 5 | W11: 5 | X11: 5 | Y11: V | Z11: A | AA11: A | AB11: A | AC11: 5 | AD11: 5 | AE11: 5 | AF11: V | AH11: =SUM(Juni[[#This Row],[1]:[30]]) -> 70
B12: Gultekin Muhammed E | C12: 4 | D12: V | E12: A | F12: A | G12: 4 | H12: 4 | I12: 4 | J12: 4 | K12: 4 | L12: A | M12: A | N12: 4 | O12: 4 | P12: 4 | Q12: 4 | R12: V | S12: A | T12: A | U12: 4 | V12: 4 | W12: 4 | X12: 4 | Y12: V | Z12: A | AA12: A | AB12: 4 | AC12: 4 | AD12: 4 | AE12: 4 | AF12: V | AH12: =SUM(Juni[[#This Row],[1]:[30]]) -> 72
B13: Irakoze Patrick | C13: 3.5 | D13: V | E13: 3.5 | F13: A | G13: A | H13: 4 | I13: 3.5 | J13: 3.5 | K13: 3.5 | L13: A | M13: A | N13: A | O13: 3.5 | P13: V | Q13: 3.5 | R13: V | S13: 3.5 | T13: 3.5 | U13: A | V13: 4 | W13: 3.5 | X13: 3.5 | Y13: V | Z13: A | AA13: 3.5 | AB13: A | AC13: 3.5 | AD13: 3.5 | AE13: 3.5 | AF13: V | AH13: =SUM(Juni[[#This Row],[1]:[30]]) -> 60.5
B14: Gultekin Eyyub | C14: 4 | D14: V | E14: A | F14: A | G14: A | H14: 4 | I14: 4 | J14: 4 | K14: 4 | L14: A | M14: A | N14: A | O14: 4 | P14: A | Q14: A | R14: V | S14: A | T14: A | U14: A | V14: A | W14: 4 | X14: 4 | Y14: V | Z14: A | AA14: A | AB14: A | AC14: A | AD14: A | AE14: 4 | AF14: V | AH14: =SUM(Juni[[#This Row],[1]:[30]]) -> 36
B15: Kefes Levent | C15: 3.5 | D15: V | E15: A | F15: A | G15: A | H15: A | I15: 3.5 | J15: 3.5 | K15: V | L15: A | M15: A | N15: A | O15: A | P15: A | Q15: A | R15: V | S15: A | T15: A | U15: A | V15: A | W15: A | X15: A | Y15: V | Z15: A | AA15: A | AB15: A | AC15: A | AD15: A | AE15: A | AF15: V | AH15: =SUM(Juni[[#This Row],[1]:[30]]) -> 10.5
B16: Moualdine Ali | C16: 5 | D16: V | E16: A | F16: A | G16: A | H16: 5 | I16: 5 | J16: 5 | K16: 5 | L16: A | M16: A | N16: A | O16: 5 | P16: 5 | Q16: 5 | R16: V | S16: A | T16: A | U16: A | V16: 5 | W16: 5 | X16: 5 | Y16: V | Z16: A | AA16: A | AB16: A | AC16: 5 | AD16: 5 | AE16: 5 | AF16: V | AH16: =SUM(Juni[[#This Row],[1]:[30]]) -> 70
B17: =MonthName&" Totaal" -> Juni Totaal | C17: =SUM(Juni[1]) -> 41 | D17: =SUM(Juni[2]) -> 0 | E17: =SUM(Juni[3]) -> 3.5 | F17: =SUM(Juni[4]) -> 4 | G17: =SUM(Juni[5]) -> 8 | H17: =SUM(Juni[6]) -> 34.5 | I17: =SUM(Juni[7]) -> 41 | J17: =SUM(Juni[8]) -> 41 | K17: =SUM(Juni[9]) -> 33.5 | L17: =SUM(Juni[10]) -> 0 | M17: =SUM(Juni[11]) -> 0 | N17: =SUM(Juni[12]) -> 4 | O17: =SUM(Juni[13]) -> 29.5 | P17: =SUM(Juni[14]) -> 30 | Q17: =SUM(Juni[15]) -> 33.5 | R17: =SUM(Juni[16]) -> 0 | S17: =SUM(Juni[17]) -> 3.5 | T17: =SUM(Juni[18]) -> 7.5 | U17: =SUM(Juni[19]) -> 8 | V17: =SUM(Juni[20]) -> 30.5 | W17: =SUM(Juni[21]) -> 37 | X17: =SUM(Juni[22]) -> 34.5 | Y17: =SUM(Juni[23]) -> 0 | Z17: =SUM(Juni[24]) -> 0 | AA17: =SUM(Juni[25]) -> 3.5 | AB17: =SUM(Juni[26]) -> 4 | AC17: =SUM(Juni[27]) -> 26 | AD17: =SUM(Juni[28]) -> 30 | AE17: =SUM(Juni[29]) -> 34 | AF17: =SUM(Juni[30]) -> 0 | AG17: =SUM(Juni[[ ]]) -> 0 | AH17: =SUBTOTAL(109,Juni[Totaal aantal uren]) -> 522

Sheet Juli
B1: =Employee_Absence_Title -> Afwezigheidsplanning Werknemers
B2: Sleutel afwezigheidstype | C2: V | D2: Vakantie | G2: P | H2: Persoonlijk | K2: Z | L2: Ziek | O2: Aangepast 1 | S2: Aangepast 2
B4: Juli | C4: Afwezigheidsdatums | AH4: =CalendarYear -> 2025
C5: =TEXT(WEEKDAY(DATE(CalendarYear,7,1),1),"aaa") -> di | D5: =TEXT(WEEKDAY(DATE(CalendarYear,7,2),1),"aaa") -> wo | E5: =TEXT(WEEKDAY(DATE(CalendarYear,7,3),1),"aaa") -> do | F5: =TEXT(WEEKDAY(DATE(CalendarYear,7,4),1),"aaa") -> vr | G5: =TEXT(WEEKDAY(DATE(CalendarYear,7,5),1),"aaa") -> za | H5: =TEXT(WEEKDAY(DATE(CalendarYear,7,6),1),"aaa") -> zo | I5: =TEXT(WEEKDAY(DATE(CalendarYear,7,7),1),"aaa") -> ma | J5: =TEXT(WEEKDAY(DATE(CalendarYear,7,8),1),"aaa") -> di | K5: =TEXT(WEEKDAY(DATE(CalendarYear,7,9),1),"aaa") -> wo | L5: =TEXT(WEEKDAY(DATE(CalendarYear,7,10),1),"aaa") -> do | M5: =TEXT(WEEKDAY(DATE(CalendarYear,7,11),1),"aaa") -> vr | N5: =TEXT(WEEKDAY(DATE(CalendarYear,7,12),1),"aaa") -> za | O5: =TEXT(WEEKDAY(DATE(CalendarYear,7,13),1),"aaa") -> zo | P5: =TEXT(WEEKDAY(DATE(CalendarYear,7,14),1),"aaa") -> ma | Q5: =TEXT(WEEKDAY(DATE(CalendarYear,7,15),1),"aaa") -> di | R5: =TEXT(WEEKDAY(DATE(CalendarYear,7,16),1),"aaa") -> wo | S5: =TEXT(WEEKDAY(DATE(CalendarYear,7,17),1),"aaa") -> do | T5: =TEXT(WEEKDAY(DATE(CalendarYear,7,18),1),"aaa") -> vr | U5: =TEXT(WEEKDAY(DATE(CalendarYear,7,19),1),"aaa") -> za | V5: =TEXT(WEEKDAY(DATE(CalendarYear,7,20),1),"aaa") -> zo | W5: =TEXT(WEEKDAY(DATE(CalendarYear,7,21),1),"aaa") -> ma | X5: =TEXT(WEEKDAY(DATE(CalendarYear,7,22),1),"aaa") -> di | Y5: =TEXT(WEEKDAY(DATE(CalendarYear,7,23),1),"aaa") -> wo | Z5: =TEXT(WEEKDAY(DATE(CalendarYear,7,24),1),"aaa") -> do | AA5: =TEXT(WEEKDAY(DATE(CalendarYear,7,25),1),"aaa") -> vr | AB5: =TEXT(WEEKDAY(DATE(CalendarYear,7,26),1),"aaa") -> za | AC5: =TEXT(WEEKDAY(DATE(CalendarYear,7,27),1),"aaa") -> zo | AD5: =TEXT(WEEKDAY(DATE(CalendarYear,7,28),1),"aaa") -> ma | AE5: =TEXT(WEEKDAY(DATE(CalendarYear,7,29),1),"aaa") -> di | AF5: =TEXT(WEEKDAY(DATE(CalendarYear,7,30),1),"aaa") -> wo | AG5: =TEXT(WEEKDAY(DATE(CalendarYear,7,31),1),"aaa") -> do
B6: Naam van werknemer | C6: 1 | D6: 2 | E6: 3 | F6: 4 | G6: 5 | H6: 6 | I6: 7 | J6: 8 | K6: 9 | L6: 10 | M6: 11 | N6: 12 | O6: 13 | P6: 14 | Q6: 15 | R6: 16 | S6: 17 | T6: 18 | U6: 19 | V6: 20 | W6: 21 | X6: 22 | Y6: 23 | Z6: 24 | AA6: 25 | AB6: 26 | AC6: 27 | AD6: 28 | AE6: 29 | AF6: 30 | AG6: 31 | AH6: Totaal aantal uren
B7: Cinar Rafet | C7: A | D7: A | E7: A | F7: A | G7: 4 | H7: 4 | I7: V | J7: V | K7: V | L7: V | M7: V | N7: V | O7: V | P7: V | Q7: V | R7: V | S7: V | T7: V | U7: V | V7: V | W7: V | X7: V | Y7: V | Z7: V | AA7: V | AB7: V | AC7: V | AD7: V | AE7: V | AF7: V | AG7: V | AH7: =SUM(Juli[[#This Row],[1]:[31]]) -> 8
B8: Eranil Mehmet Fatih | C8: A | D8: A | E8: A | F8: 3.5 | G8: 3.5 | H8: 3.5 | I8: V | J8: V | K8: V | L8: V | M8: V | N8: V | O8: V | P8: V | Q8: V | R8: V | S8: V | T8: V | U8: V | V8: V | W8: V | X8: V | Y8: V | Z8: V | AA8: V | AB8: V | AC8: V | AD8: V | AE8: V | AF8: V | AG8: V | AH8: =SUM(Juli[[#This Row],[1]:[31]]) -> 10.5
B9: El Karmoudi Taufik | C9: A | D9: A | E9: A | F9: 5 | G9: 5 | H9: 5 | I9: V | J9: V | K9: V | L9: V | M9: V | N9: V | O9: V | P9: V | Q9: V | R9: V | S9: V | T9: V | U9: V | V9: V | W9: V | X9: V | Y9: V | Z9: V | AA9: V | AB9: V | AC9: V | AD9: V | AE9: V | AF9: V | AG9: V | AH9: =SUM(Juli[[#This Row],[1]:[31]]) -> 15
B10: El Maazouzi Abdelilah | C10: A | D10: 4 | E10: 4 | F10: 4 | G10: 4 | H10: 4 | I10: V | J10: V | K10: V | L10: V | M10: V | N10: V | O10: V | P10: V | Q10: V | R10: V | S10: V | T10: V | U10: V | V10: V | W10: V | X10: V | Y10: V | Z10: V | AA10: V | AB10: V | AC10: V | AD10: V | AE10: V | AF10: V | AG10: V | AH10: =SUM(Juli[[#This Row],[1]:[31]]) -> 20
B11: Gultekin Muhammed E | C11: A | D11: A | E11: 4 | F11: 4 | G11: 4 | H11: 4 | I11: V | J11: V | K11: V | L11: V | M11: V | N11: V | O11: V | P11: V | Q11: V | R11: V | S11: V | T11: V | U11: V | V11: V | W11: V | X11: V | Y11: V | Z11: V | AA11: V | AB11: V | AC11: V | AD11: V | AE11: V | AF11: V | AG11: V | AH11: =SUM(Juli[[#This Row],[1]:[31]]) -> 16
B12: Irakoze Patrick | C12: 3.5 | D12: 3.5 | E12: A | F12: 3.5 | G12: V | H12: 3.5 | I12: V | J12: V | K12: V | L12: V | M12: V | N12: V | O12: V | P12: V | Q12: V | R12: V | S12: V | T12: V | U12: V | V12: V | W12: V | X12: V | Y12: V | Z12: V | AA12: V | AB12: V | AC12: V | AD12: V | AE12: V | AF12: V | AG12: V | AH12: =SUM(Juli[[#This Row],[1]:[31]]) -> 14
B13: Moualdine Ali | C13: A | D13: A | E13: A | F13: 5 | G13: 5 | H13: 5 | I13: V | J13: V | K13: V | L13: V | M13: V | N13: V | O13: V | P13: V | Q13: V | R13: V | S13: V | T13: V | U13: V | V13: V | W13: V | X13: V | Y13: V | Z13: V | AA13: V | AB13: V | AC13: V | AD13: V | AE13: V | AF13: V | AG13: V | AH13: =SUM(Juli[[#This Row],[1]:[31]]) -> 15
B14: =MonthName&" Totaal" -> Juli Totaal | C14: =SUM(Juli[1]) -> 3.5 | D14: =SUM(Juli[2]) -> 7.5 | E14: =SUM(Juli[3]) -> 8 | F14: =SUM(Juli[4]) -> 25 | G14: =SUM(Juli[5]) -> 25.5 | H14: =SUM(Juli[6]) -> 29 | I14: =SUM(Juli[7]) -> 0 | J14: =SUM(Juli[8]) -> 0 | K14: =SUM(Juli[9]) -> 0 | L14: =SUM(Juli[10]) -> 0 | M14: =SUM(Juli[11]) -> 0 | N14: =SUM(Juli[12]) -> 0 | O14: =SUM(Juli[13]) -> 0 | P14: =SUM(Juli[14]) -> 0 | Q14: =SUM(Juli[15]) -> 0 | R14: =SUM(Juli[16]) -> 0 | S14: =SUM(Juli[17]) -> 0 | T14: =SUM(Juli[18]) -> 0 | U14: =SUM(Juli[19]) -> 0 | V14: =SUM(Juli[20]) -> 0 | W14: =SUM(Juli[21]) -> 0 | X14: =SUM(Juli[22]) -> 0 | Y14: =SUM(Juli[23]) -> 0 | Z14: =SUM(Juli[24]) -> 0 | AA14: =SUM(Juli[25]) -> 0 | AB14: =SUM(Juli[26]) -> 0 | AC14: =SUM(Juli[27]) -> 0 | AD14: =SUM(Juli[28]) -> 0 | AE14: =SUM(Juli[29]) -> 0 | AF14: =SUM(Juli[30]) -> 0 | AG14: =SUM(Juli[31]) -> 0 | AH14: =SUBTOTAL(109,Juli[Totaal aantal uren]) -> 98.5

Sheet Augustus
B1: =Employee_Absence_Title -> Afwezigheidsplanning Werknemers
B2: Sleutel afwezigheidstype | C2: V | D2: Vakantie | G2: P | H2: Persoonlijk | K2: Z | L2: Ziek | O2: Aangepast 1 | S2: Aangepast 2
B4: Augustus | C4: Afwezigheidsdatums | AH4: =CalendarYear -> 2025
C5: =TEXT(WEEKDAY(DATE(CalendarYear,8,1),1),"aaa") -> vr | D5: =TEXT(WEEKDAY(DATE(CalendarYear,8,2),1),"aaa") -> za | E5: =TEXT(WEEKDAY(DATE(CalendarYear,8,3),1),"aaa") -> zo | F5: =TEXT(WEEKDAY(DATE(CalendarYear,8,4),1),"aaa") -> ma | G5: =TEXT(WEEKDAY(DATE(CalendarYear,8,5),1),"aaa") -> di | H5: =TEXT(WEEKDAY(DATE(CalendarYear,8,6),1),"aaa") -> wo | I5: =TEXT(WEEKDAY(DATE(CalendarYear,8,7),1),"aaa") -> do | J5: =TEXT(WEEKDAY(DATE(CalendarYear,8,8),1),"aaa") -> vr | K5: =TEXT(WEEKDAY(DATE(CalendarYear,8,9),1),"aaa") -> za | L5: =TEXT(WEEKDAY(DATE(CalendarYear,8,10),1),"aaa") -> zo | M5: =TEXT(WEEKDAY(DATE(CalendarYear,8,11),1),"aaa") -> ma | N5: =TEXT(WEEKDAY(DATE(CalendarYear,8,12),1),"aaa") -> di | O5: =TEXT(WEEKDAY(DATE(CalendarYear,8,13),1),"aaa") -> wo | P5: =TEXT(WEEKDAY(DATE(CalendarYear,8,14),1),"aaa") -> do | Q5: =TEXT(WEEKDAY(DATE(CalendarYear,8,15),1),"aaa") -> vr | R5: =TEXT(WEEKDAY(DATE(CalendarYear,8,16),1),"aaa") -> za | S5: =TEXT(WEEKDAY(DATE(CalendarYear,8,17),1),"aaa") -> zo | T5: =TEXT(WEEKDAY(DATE(CalendarYear,8,18),1),"aaa") -> ma | U5: =TEXT(WEEKDAY(DATE(CalendarYear,8,19),1),"aaa") -> di | V5: =TEXT(WEEKDAY(DATE(CalendarYear,8,20),1),"aaa") -> wo | W5: =TEXT(WEEKDAY(DATE(CalendarYear,8,21),1),"aaa") -> do | X5: =TEXT(WEEKDAY(DATE(CalendarYear,8,22),1),"aaa") -> vr | Y5: =TEXT(WEEKDAY(DATE(CalendarYear,8,23),1),"aaa") -> za | Z5: =TEXT(WEEKDAY(DATE(CalendarYear,8,24),1),"aaa") -> zo | AA5: =TEXT(WEEKDAY(DATE(CalendarYear,8,25),1),"aaa") -> ma | AB5: =TEXT(WEEKDAY(DATE(CalendarYear,8,26),1),"aaa") -> di | AC5: =TEXT(WEEKDAY(DATE(CalendarYear,8,27),1),"aaa") -> wo | AD5: =TEXT(WEEKDAY(DATE(CalendarYear,8,28),1),"aaa") -> do | AE5: =TEXT(WEEKDAY(DATE(CalendarYear,8,29),1),"aaa") -> vr | AF5: =TEXT(WEEKDAY(DATE(CalendarYear,8,30),1),"aaa") -> za | AG5: =TEXT(WEEKDAY(DATE(CalendarYear,8,31),1),"aaa") -> zo
B6: Naam van werknemer | C6: 1 | D6: 2 | E6: 3 | F6: 4 | G6: 5 | H6: 6 | I6: 7 | J6: 8 | K6: 9 | L6: 10 | M6: 11 | N6: 12 | O6: 13 | P6: 14 | Q6: 15 | R6: 16 | S6: 17 | T6: 18 | U6: 19 | V6: 20 | W6: 21 | X6: 22 | Y6: 23 | Z6: 24 | AA6: 25 | AB6: 26 | AC6: 27 | AD6: 28 | AE6: 29 | AF6: 30 | AG6: 31 | AH6: Totaal aantal uren
B7: Biragoye Isaac | C7: V | D7: V | E7: V | F7: V | G7: V | H7: V | I7: V | J7: V | K7: V | L7: V | M7: V | N7: V | O7: V | P7: V | Q7: V | R7: V | S7: V | T7: V | U7: V | V7: V | W7: V | X7: V | Y7: V | Z7: V | AA7: V | AB7: V | AC7: V | AD7: V | AE7: 4 | AF7: 3.5 | AG7: 3.5 | AH7: =SUM(Augustus[[#This Row],[1]:[31]]) -> 11
B8: El Karmoudi Taufik | C8: V | D8: V | E8: V | F8: V | G8: V | H8: V | I8: V | J8: V | K8: V | L8: V | M8: V | N8: V | O8: V | P8: V | Q8: V | R8: V | S8: V | T8: V | U8: V | V8: V | W8: V | X8: V | Y8: V | Z8: V | AA8: V | AB8: V | AC8: V | AD8: V | AE8: 5 | AF8: 5 | AG8: 5 | AH8: =SUM(Augustus[[#This Row],[1]:[31]]) -> 15
B9: El Maazouzi Abdelilah | C9: V | D9: V | E9: V | F9: V | G9: V | H9: V | I9: V | J9: V | K9: V | L9: V | M9: V | N9: V | O9: V | P9: V | Q9: V | R9: V | S9: V | T9: V | U9: V | V9: V | W9: V | X9: V | Y9: V | Z9: V | AA9: V | AB9: V | AC9: V | AD9: V | AE9: 4 | AF9: 4 | AG9: 4 | AH9: =SUM(Augustus[[#This Row],[1]:[31]]) -> 12
B10: Gultekin Muhammed A | C10: V | D10: V | E10: V | F10: V | G10: V | H10: V | I10: V | J10: V | K10: V | L10: V | M10: V | N10: V | O10: V | P10: V | Q10: V | R10: V | S10: V | T10: V | U10: V | V10: V | W10: V | X10: V | Y10: V | Z10: V | AA10: V | AB10: V | AC10: V | AD10: V | AE10: V | AF10: 5 | AG10: 5 | AH10: =SUM(Augustus[[#This Row],[1]:[31]]) -> 10
B11: Gultekin Muhammed E | C11: V | D11: V | E11: V | F11: V | G11: V | H11: V | I11: V | J11: V | K11: V | L11: V | M11: V | N11: V | O11: V | P11: V | Q11: V | R11: V | S11: V | T11: V | U11: V | V11: V | W11: V | X11: V | Y11: V | Z11: V | AA11: V | AB11: V | AC11: V | AD11: V | AE11: 5 | AF11: 5 | AG11: 5 | AH11: =SUM(Augustus[[#This Row],[1]:[31]]) -> 15
B12: Moualdine Ali | C12: V | D12: V | E12: V | F12: V | G12: V | H12: V | I12: V | J12: V | K12: V | L12: V | M12: V | N12: V | O12: V | P12: V | Q12: V | R12: V | S12: V | T12: V | U12: V | V12: V | W12: V | X12: V | Y12: V | Z12: V | AA12: V | AB12: V | AC12: V | AD12: V | AE12: 5 | AF12: 5 | AG12: 5 | AH12: =SUM(Augustus[[#This Row],[1]:[31]]) -> 15
B13: Eranil Mehmet Fatih | C13: V | D13: V | E13: V | F13: V | G13: V | H13: V | I13: V | J13: V | K13: V | L13: V | M13: V | N13: V | O13: V | P13: V | Q13: V | R13: V | S13: V | T13: V | U13: V | V13: V | W13: V | X13: V | Y13: V | Z13: V | AA13: V | AB13: V | AC13: V | AD13: V | AE13: 3.5 | AF13: 3.5 | AG13: 3.5 | AH13: =SUM(Augustus[[#This Row],[1]:[31]]) -> 10.5
B14: =MonthName&" Totaal" -> Augustus Totaal | C14: =SUM(Augustus[1]) -> 0 | D14: =SUM(Augustus[2]) -> 0 | E14: =SUM(Augustus[3]) -> 0 | F14: =SUM(Augustus[4]) -> 0 | G14: =SUM(Augustus[5]) -> 0 | H14: =SUM(Augustus[6]) -> 0 | I14: =SUM(Augustus[7]) -> 0 | J14: =SUM(Augustus[8]) -> 0 | K14: =SUM(Augustus[9]) -> 0 | L14: =SUM(Augustus[10]) -> 0 | M14: =SUM(Augustus[11]) -> 0 | N14: =SUM(Augustus[12]) -> 0 | O14: =SUM(Augustus[13]) -> 0 | P14: =SUM(Augustus[14]) -> 0 | Q14: =SUM(Augustus[15]) -> 0 | R14: =SUM(Augustus[16]) -> 0 | S14: =SUM(Augustus[17]) -> 0 | T14: =SUM(Augustus[18]) -> 0 | U14: =SUM(Augustus[19]) -> 0 | V14: =SUM(Augustus[20]) -> 0 | W14: =SUM(Augustus[21]) -> 0 | X14: =SUM(Augustus[22]) -> 0 | Y14: =SUM(Augustus[23]) -> 0 | Z14: =SUM(Augustus[24]) -> 0 | AA14: =SUM(Augustus[25]) -> 0 | AB14: =SUM(Augustus[26]) -> 0 | AC14: =SUM(Augustus[27]) -> 0 | AD14: =SUM(Augustus[28]) -> 0 | AE14: =SUM(Augustus[29]) -> 26.5 | AF14: =SUM(Augustus[30]) -> 31 | AG14: =SUM(Augustus[31]) -> 31 | AH14: =SUBTOTAL(109,Augustus[Totaal aantal uren]) -> 88.5

Sheet September
B1: =Employee_Absence_Title -> Afwezigheidsplanning Werknemers
B2: Sleutel afwezigheidstype | C2: V | D2: Vakantie | G2: P | H2: Persoonlijk | K2: Z | L2: Ziek | O2: Aangepast 1 | S2: Aangepast 2
B4: september | C4: Afwezigheidsdatums | AH4: =CalendarYear -> 2025
C5: =TEXT(WEEKDAY(DATE(CalendarYear,9,1),1),"aaa") -> ma | D5: =TEXT(WEEKDAY(DATE(CalendarYear,9,2),1),"aaa") -> di | E5: =TEXT(WEEKDAY(DATE(CalendarYear,9,3),1),"aaa") -> wo | F5: =TEXT(WEEKDAY(DATE(CalendarYear,9,4),1),"aaa") -> do | G5: =TEXT(WEEKDAY(DATE(CalendarYear,9,5),1),"aaa") -> vr | H5: =TEXT(WEEKDAY(DATE(CalendarYear,9,6),1),"aaa") -> za | I5: =TEXT(WEEKDAY(DATE(CalendarYear,9,7),1),"aaa") -> zo | J5: =TEXT(WEEKDAY(DATE(CalendarYear,9,8),1),"aaa") -> ma | K5: =TEXT(WEEKDAY(DATE(CalendarYear,9,9),1),"aaa") -> di | L5: =TEXT(WEEKDAY(DATE(CalendarYear,9,10),1),"aaa") -> wo | M5: =TEXT(WEEKDAY(DATE(CalendarYear,9,11),1),"aaa") -> do | N5: =TEXT(WEEKDAY(DATE(CalendarYear,9,12),1),"aaa") -> vr | O5: =TEXT(WEEKDAY(DATE(CalendarYear,9,13),1),"aaa") -> za | P5: =TEXT(WEEKDAY(DATE(CalendarYear,9,14),1),"aaa") -> zo | Q5: =TEXT(WEEKDAY(DATE(CalendarYear,9,15),1),"aaa") -> ma | R5: =TEXT(WEEKDAY(DATE(CalendarYear,9,16),1),"aaa") -> di | S5: =TEXT(WEEKDAY(DATE(CalendarYear,9,17),1),"aaa") -> wo | T5: =TEXT(WEEKDAY(DATE(CalendarYear,9,18),1),"aaa") -> do | U5: =TEXT(WEEKDAY(DATE(CalendarYear,9,19),1),"aaa") -> vr | V5: =TEXT(WEEKDAY(DATE(CalendarYear,9,20),1),"aaa") -> za | W5: =TEXT(WEEKDAY(DATE(CalendarYear,9,21),1),"aaa") -> zo | X5: =TEXT(WEEKDAY(DATE(CalendarYear,9,22),1),"aaa") -> ma | Y5: =TEXT(WEEKDAY(DATE(CalendarYear,9,23),1),"aaa") -> di | Z5: =TEXT(WEEKDAY(DATE(CalendarYear,9,24),1),"aaa") -> wo | AA5: =TEXT(WEEKDAY(DATE(CalendarYear,9,25),1),"aaa") -> do | AB5: =TEXT(WEEKDAY(DATE(CalendarYear,9,26),1),"aaa") -> vr | AC5: =TEXT(WEEKDAY(DATE(CalendarYear,9,27),1),"aaa") -> za | AD5: =TEXT(WEEKDAY(DATE(CalendarYear,9,28),1),"aaa") -> zo | AE5: =TEXT(WEEKDAY(DATE(CalendarYear,9,29),1),"aaa") -> ma | AF5: =TEXT(WEEKDAY(DATE(CalendarYear,9,30),1),"aaa") -> di
B6: Naam van werknemer | C6: 1 | D6: 2 | E6: 3 | F6: 4 | G6: 5 | H6: 6 | I6: 7 | J6: 8 | K6: 9 | L6: 10 | M6: 11 | N6: 12 | O6: 13 | P6: 14 | Q6: 15 | R6: 16 | S6: 17 | T6: 18 | U6: 19 | V6: 20 | W6: 21 | X6: 22 | Y6: 23 | Z6: 24 | AA6: 25 | AB6: 26 | AC6: 27 | AD6: 28 | AE6: 29 | AF6: 30 | AH6: Totaal aantal uren
B7: Biragoye Isaac | C7: V | D7: A | E7: A | F7: A | G7: 3.5 | H7: 3.5 | I7: 3.5 | J7: V | K7: A | L7: A | M7: A | N7: 3.5 | O7: 3 | P7: 3.5 | Q7: V | R7: A | S7: A | T7: A | U7: 3.5 | V7: 3.5 | W7: 3.5 | X7: V | Y7: A | Z7: A | AA7: A | AB7: 3.5 | AC7: 3.5 | AD7: 3.5 | AE7: V | AF7: A | AH7: =SUM(September[[#This Row],[1]:[30]]) -> 41.5
B8: Cinar Rafet | C8: V | D8: A | E8: A | F8: A | G8: A | H8: 5 | I8: 5 | J8: V | K8: A | L8: A | M8: A | N8: A | O8: 5 | P8: 5 | Q8: V | R8: A | S8: A | T8: A | U8: A | V8: A | W8: A | X8: V | Y8: A | Z8: A | AA8: A | AB8: A | AC8: A | AD8: A | AE8: V | AF8: A | AH8: =SUM(September[[#This Row],[1]:[30]]) -> 20
B9: Eranil Mehmet Onur | C9: V | D9: A | E9: A | F9: A | G9: 3.5 | H9: 3.5 | I9: 3.5 | J9: V | K9: A | L9: A | M9: A | N9: 3.5 | O9: 3.5 | P9: 3.5 | Q9: V | R9: A | S9: A | T9: A | U9: 3.5 | V9: 3.5 | W9: 3.5 | X9: V | Y9: A | Z9: A | AA9: A | AB9: 3.5 | AC9: 3.5 | AD9: 3.5 | AE9: V | AF9: A | AH9: =SUM(September[[#This Row],[1]:[30]]) -> 42
B10: El Karmoudi Taufik | C10: V | D10: A | E10: A | F10: A | G10: 5 | H10: 5 | I10: 5 | J10: V | K10: A | L10: A | M10: A | N10: 5 | O10: 5 | P10: 5 | Q10: V | R10: A | S10: A | T10: A | U10: 5 | V10: 5 | W10: 5 | X10: V | Y10: A | Z10: A | AA10: A | AB10: 5 | AC10: 5 | AD10: 5 | AE10: V | AF10: A | AH10: =SUM(September[[#This Row],[1]:[30]]) -> 60
B11: El Maazouzi Abdelilah | C11: V | D11: A | E11: A | F11: A | G11: A | H11: 4 | I11: 4 | J11: V | K11: A | L11: 4 | M11: 4 | N11: 4 | O11: 4 | P11: 4 | Q11: V | R11: A | S11: A | T11: A | U11: A | V11: 4 | W11: 4 | X11: V | Y11: A | Z11: 4 | AA11: 4 | AB11: 4 | AC11: 4 | AD11: 4 | AE11: V | AF11: A | AH11: =SUM(September[[#This Row],[1]:[30]]) -> 56
B12: Gultekin Muhammed A | C12: V | D12: A | E12: A | F12: A | G12: 5 | H12: 5 | I12: 5 | J12: V | K12: A | L12: A | M12: A | N12: 5 | O12: 5 | P12: 5 | Q12: V | R12: A | S12: A | T12: A | U12: 5 | V12: 5 | W12: 5 | X12: V | Y12: A | Z12: A | AA12: A | AB12: 5 | AC12: 5 | AD12: 5 | AE12: V | AF12: A | AH12: =SUM(September[[#This Row],[1]:[30]]) -> 60
